Workbook

Sheet Summary
A1: Universe summary
A2: All counts are live formulas on the Universe tab - update coverage there and these refresh.
A4: Total names | B4: =COUNTA(Universe!$A$5:$A$241) -> 237
A5: Coverage verified as zero | B5: =COUNTIF(Universe!$H$5:$H$241,"0 (checked)") -> 10
A6: Coverage still unverified | B6: =COUNTIF(Universe!$H$5:$H$241,"Unverified") -> 223
A7: Tradable names (>= $50M) | B7: =SUM(Universe!$K$5:$K$241) -> 207
A8: Combined market cap ($M) | B8: =SUM(Universe!$C$5:$C$241) -> 53091.32
A10: By archetype
A11: Archetype | B11: Names | C11: Mkt cap ($M) | D11: Avg priority
A12: Community bank | B12: =COUNTIF(Universe!$D$5:$D$241,A12) -> 110 | C12: =SUMIF(Universe!$D$5:$D$241,A12,Universe!$C$5:$C$241) -> 27850.14 | D12: =AVERAGEIF(Universe!$D$5:$D$241,A12,Universe!$M$5:$M$241) -> 6.9727273
A13: Regulated utility | B13: =COUNTIF(Universe!$D$5:$D$241,A13) -> 6 | C13: =SUMIF(Universe!$D$5:$D$241,A13,Universe!$C$5:$C$241) -> 1965.28 | D13: =AVERAGEIF(Universe!$D$5:$D$241,A13,Universe!$M$5:$M$241) -> 7
A14: Energy project developer | B14: =COUNTIF(Universe!$D$5:$D$241,A14) -> 4 | C14: =SUMIF(Universe!$D$5:$D$241,A14,Universe!$C$5:$C$241) -> 724.41 | D14: =AVERAGEIF(Universe!$D$5:$D$241,A14,Universe!$M$5:$M$241) -> 6.5
A15: Land / entitlement developer | B15: =COUNTIF(Universe!$D$5:$D$241,A15) -> 14 | C15: =SUMIF(Universe!$D$5:$D$241,A15,Universe!$C$5:$C$241) -> 3428.32 | D15: =AVERAGEIF(Universe!$D$5:$D$241,A15,Universe!$M$5:$M$241) -> 8.0357143
A16: Property owner (commercial) | B16: =COUNTIF(Universe!$D$5:$D$241,A16) -> 18 | C16: =SUMIF(Universe!$D$5:$D$241,A16,Universe!$C$5:$C$241) -> 3380.81 | D16: =AVERAGEIF(Universe!$D$5:$D$241,A16,Universe!$M$5:$M$241) -> 5.7777778
A17: Apartment owner | B17: =COUNTIF(Universe!$D$5:$D$241,A17) -> 8 | C17: =SUMIF(Universe!$D$5:$D$241,A17,Universe!$C$5:$C$241) -> 1908.84 | D17: =AVERAGEIF(Universe!$D$5:$D$241,A17,Universe!$M$5:$M$241) -> 8
A18: RE transaction platform | B18: =COUNTIF(Universe!$D$5:$D$241,A18) -> 3 | C18: =SUMIF(Universe!$D$5:$D$241,A18,Universe!$C$5:$C$241) -> 156.94 | D18: =AVERAGEIF(Universe!$D$5:$D$241,A18,Universe!$M$5:$M$241) -> 5.3333333
A19: Hotel owner | B19: =COUNTIF(Universe!$D$5:$D$241,A19) -> 4 | C19: =SUMIF(Universe!$D$5:$D$241,A19,Universe!$C$5:$C$241) -> 223.46 | D19: =AVERAGEIF(Universe!$D$5:$D$241,A19,Universe!$M$5:$M$241) -> 6.75
A20: Farmland / water rights | B20: =COUNTIF(Universe!$D$5:$D$241,A20) -> 3 | C20: =SUMIF(Universe!$D$5:$D$241,A20,Universe!$C$5:$C$241) -> 1289.16 | D20: =AVERAGEIF(Universe!$D$5:$D$241,A20,Universe!$M$5:$M$241) -> 6
A21: Regional gaming / racing | B21: =COUNTIF(Universe!$D$5:$D$241,A21) -> 3 | C21: =SUMIF(Universe!$D$5:$D$241,A21,Universe!$C$5:$C$241) -> 161.84 | D21: =AVERAGEIF(Universe!$D$5:$D$241,A21,Universe!$M$5:$M$241) -> 8
A22: Oil & gas producer / royalty | B22: =COUNTIF(Universe!$D$5:$D$241,A22) -> 21 | C22: =SUMIF(Universe!$D$5:$D$241,A22,Universe!$C$5:$C$241) -> 2666.23 | D22: =AVERAGEIF(Universe!$D$5:$D$241,A22,Universe!$M$5:$M$241) -> 6.7142857
A23: Midstream / energy infrastructure | B23: =COUNTIF(Universe!$D$5:$D$241,A23) -> 4 | C23: =SUMIF(Universe!$D$5:$D$241,A23,Universe!$C$5:$C$241) -> 621.79 | D23: =AVERAGEIF(Universe!$D$5:$D$241,A23,Universe!$M$5:$M$241) -> 5.75
... A30: Government-funded services | B30: =COUNTIF(Universe!$D$5:$D$241,A30) -> 3 | C30: =SUMIF(Universe!$D$5:$D$241,A30,Universe!$C$5:$C$241) -> 378.93 | D30: =AVERAGEIF(Universe!$D$5:$D$241,A30,Universe!$M$5:$M$241) -> 6.6666667
A31: Total | B31: =SUM(B12:B30) -> 237 | C31: =SUM(C12:C30) -> 53091.32

Sheet Universe
A1: Microcap local-government universe - 237 US-listed names under $500M
A2: Built from StockAnalysis.com industry lists (Oct 16, 2026), filtered to market cap < $500M and to companies where a local/state government decision or a public dataset plausibly drives fundamentals. Foreign-operating, shell and pure consumer/tech names removed. Sorted by Priority (highest first). Use the filters in row 4.
A4: Ticker | B4: Company | C4: Mkt cap ($M) | D4: Archetype | E4: Local-gov driver | F4: Public data to ingest | G4: Note | H4: Analyst coverage | I4: Local-gov intensity (1-3) | J4: Data edge (1-3) | K4: Tradable (>= $50M) | L4: Coverage pts | M4: Priority | N4: Size band
A5: TRC | B5: Tejon Ranch | C5: 437.21 | D5: Land / entitlement developer | E5: Value unlocked by entitlements, zoning, plats and permits on specific parcels | F5: Planning commission & council agendas; plat approvals; Census BPS; county deed and assessor records | G5: Kern/LA County entitlements; CEQA litigation; water | H5: 0 (checked) | I5: 3 | J5: 3 | K5: =IF(C5>=50,1,0) -> 1 | L5: =IF(H5="0 (checked)",2,IF(H5="Unverified",1,IF(H5="1 (checked)",0.5,0))) -> 2 | M5: =I5+J5+K5+L5 -> 9 | N5: =IF(C5<25,"Nano (<$25M)",IF(C5<100,"$25-100M",IF(C5<250,"$100-250M","$250-500M"))) -> $250-500M
A6: MLP | B6: Maui Land & Pineapple | C6: 295.9 | D6: Land / entitlement developer | E6: Value unlocked by entitlements, zoning, plats and permits on specific parcels | F6: Planning commission & council agendas; plat approvals; Census BPS; county deed and assessor records | G6: Maui County & state water decisions; water-asset strategic review | H6: 0 (checked) | I6: 3 | J6: 3 | K6: =IF(C6>=50,1,0) -> 1 | L6: =IF(H6="0 (checked)",2,IF(H6="Unverified",1,IF(H6="1 (checked)",0.5,0))) -> 2 | M6: =I6+J6+K6+L6 -> 9 | N6: =IF(C6<25,"Nano (<$25M)",IF(C6<100,"$25-100M",IF(C6<250,"$100-250M","$250-500M"))) -> $250-500M
A7: CPHC | B7: Canterbury Park | C7: 81.64 | D7: Regional gaming / racing | E7: State gaming & racing commissions license and tax; local approvals for expansions | F7: Monthly state gaming-revenue reports by property; racing commission minutes; city development agendas | G7: Shakopee TIF; MN Racing Commission; sports-betting bills | H7: 0 (checked) | I7: 3 | J7: 3 | K7: =IF(C7>=50,1,0) -> 1 | L7: =IF(H7="0 (checked)",2,IF(H7="Unverified",1,IF(H7="1 (checked)",0.5,0))) -> 2 | M7: =I7+J7+K7+L7 -> 9 | N7: =IF(C7<25,"Nano (<$25M)",IF(C7<100,"$25-100M",IF(C7<250,"$100-250M","$250-500M"))) -> $25-100M
A8: SDHC | B8: Smith Douglas Homes | C8: 497.1 | D8: Land / entitlement developer | E8: Value unlocked by entitlements, zoning, plats and permits on specific parcels | F8: Planning commission & council agendas; plat approvals; Census BPS; county deed and assessor records | G8: Southeast homebuilder - lot approvals & permits | H8: Unverified | I8: 3 | J8: 3 | K8: =IF(C8>=50,1,0) -> 1 | L8: =IF(H8="0 (checked)",2,IF(H8="Unverified",1,IF(H8="1 (checked)",0.5,0))) -> 1 | M8: =I8+J8+K8+L8 -> 8 | N8: =IF(C8<25,"Nano (<$25M)",IF(C8<100,"$25-100M",IF(C8<250,"$100-250M","$250-500M"))) -> $250-500M
A9: AII | B9: American Integrity Insurance | C9: 488.46 | D9: State-regulated P&C insurer | E9: State insurance departments approve rates; catastrophe reforms in specific states | F9: SERFF rate filings; state insurance dept market-share and complaint data | G9: Florida OIR | H9: Unverified | I9: 3 | J9: 3 | K9: =IF(C9>=50,1,0) -> 1 | L9: =IF(H9="0 (checked)",2,IF(H9="Unverified",1,IF(H9="1 (checked)",0.5,0))) -> 1 | M9: =I9+J9+K9+L9 -> 8 | N9: =IF(C9<25,"Nano (<$25M)",IF(C9<100,"$25-100M",IF(C9<250,"$100-250M","$250-500M"))) -> $250-500M
A10: NXRT | B10: NexPoint Residential Trust | C10: 469.19 | D10: Apartment owner | E10: Rents shaped by local rent rules and new-supply permits in specific metros | F10: Local rent boards (e.g., NYC Rent Guidelines Board); multifamily permits; eviction filings; property-tax assessments | H10: Unverified | I10: 3 | J10: 3 | K10: =IF(C10>=50,1,0) -> 1 | L10: =IF(H10="0 (checked)",2,IF(H10="Unverified",1,IF(H10="1 (checked)",0.5,0))) -> 1 | M10: =I10+J10+K10+L10 -> 8 | N10: =IF(C10<25,"Nano (<$25M)",IF(C10<100,"$25-100M",IF(C10<250,"$100-250M","$250-500M"))) -> $250-500M
A11: BBCP | B11: Concrete Pumping | C11: 457.57 | D11: Public-works contractor | E11: Revenue won through state DOT, municipal and utility contract lettings | F11: State DOT bid lettings & awards; municipal procurement portals; utility capex filings | H11: Unverified | I11: 3 | J11: 3 | K11: =IF(C11>=50,1,0) -> 1 | L11: =IF(H11="0 (checked)",2,IF(H11="Unverified",1,IF(H11="1 (checked)",0.5,0))) -> 1 | M11: =I11+J11+K11+L11 -> 8 | N11: =IF(C11<25,"Nano (<$25M)",IF(C11<100,"$25-100M",IF(C11<250,"$100-250M","$250-500M"))) -> $250-500M
A12: TCI | B12: Transcontinental Realty Investors | C12: 431.42 | D12: Land / entitlement developer | E12: Value unlocked by entitlements, zoning, plats and permits on specific parcels | F12: Planning commission & council agendas; plat approvals; Census BPS; county deed and assessor records | G12: Texas land & apartments | H12: Unverified | I12: 3 | J12: 3 | K12: =IF(C12>=50,1,0) -> 1 | L12: =IF(H12="0 (checked)",2,IF(H12="Unverified",1,IF(H12="1 (checked)",0.5,0))) -> 1 | M12: =I12+J12+K12+L12 -> 8 | N12: =IF(C12<25,"Nano (<$25M)",IF(C12<100,"$25-100M",IF(C12<250,"$100-250M","$250-500M"))) -> $250-500M
A13: ACIC | B13: American Coastal Insurance | C13: 421.86 | D13: State-regulated P&C insurer | E13: State insurance departments approve rates; catastrophe reforms in specific states | F13: SERFF rate filings; state insurance dept market-share and complaint data | G13: Florida OIR | H13: Unverified | I13: 3 | J13: 3 | K13: =IF(C13>=50,1,0) -> 1 | L13: =IF(H13="0 (checked)",2,IF(H13="Unverified",1,IF(H13="1 (checked)",0.5,0))) -> 1 | M13: =I13+J13+K13+L13 -> 8 | N13: =IF(C13<25,"Nano (<$25M)",IF(C13<100,"$25-100M",IF(C13<250,"$100-250M","$250-500M"))) -> $250-500M
A14: CYH | B14: Community Health Systems | C14: 405.23 | D14: Healthcare facility operator | E14: State certificate-of-need, Medicaid rates and supplemental payments | F14: State CON dockets; Medicaid fee schedules; CMS hospital cost reports | G14: State CON & Medicaid supplemental payments | H14: Unverified | I14: 3 | J14: 3 | K14: =IF(C14>=50,1,0) -> 1 | L14: =IF(H14="0 (checked)",2,IF(H14="Unverified",1,IF(H14="1 (checked)",0.5,0))) -> 1 | M14: =I14+J14+K14+L14 -> 8 | N14: =IF(C14<25,"Nano (<$25M)",IF(C14<100,"$25-100M",IF(C14<250,"$100-250M","$250-500M"))) -> $250-500M
A15: GBLI | B15: Global Indemnity | C15: 371.64 | D15: State-regulated P&C insurer | E15: State insurance departments approve rates; catastrophe reforms in specific states | F15: SERFF rate filings; state insurance dept market-share and complaint data | H15: Unverified | I15: 3 | J15: 3 | K15: =IF(C15>=50,1,0) -> 1 | L15: =IF(H15="0 (checked)",2,IF(H15="Unverified",1,IF(H15="1 (checked)",0.5,0))) -> 1 | M15: =I15+J15+K15+L15 -> 8 | N15: =IF(C15<25,"Nano (<$25M)",IF(C15<100,"$25-100M",IF(C15<250,"$100-250M","$250-500M"))) -> $250-500M
A16: BSRT | B16: BSR REIT | C16: 358.72 | D16: Apartment owner | E16: Rents shaped by local rent rules and new-supply permits in specific metros | F16: Local rent boards (e.g., NYC Rent Guidelines Board); multifamily permits; eviction filings; property-tax assessments | G16: Sunbelt apartments | H16: Unverified | I16: 3 | J16: 3 | K16: =IF(C16>=50,1,0) -> 1 | L16: =IF(H16="0 (checked)",2,IF(H16="Unverified",1,IF(H16="1 (checked)",0.5,0))) -> 1 | M16: =I16+J16+K16+L16 -> 8 | N16: =IF(C16<25,"Nano (<$25M)",IF(C16<100,"$25-100M",IF(C16<250,"$100-250M","$250-500M"))) -> $250-500M
A17: ORN | B17: Orion Group Holdings | C17: 345.02 | D17: Public-works contractor | E17: Revenue won through state DOT, municipal and utility contract lettings | F17: State DOT bid lettings & awards; municipal procurement portals; utility capex filings | G17: Marine/port public works | H17: Unverified | I17: 3 | J17: 3 | K17: =IF(C17>=50,1,0) -> 1 | L17: =IF(H17="0 (checked)",2,IF(H17="Unverified",1,IF(H17="1 (checked)",0.5,0))) -> 1 | M17: =I17+J17+K17+L17 -> 8 | N17: =IF(C17<25,"Nano (<$25M)",IF(C17<100,"$25-100M",IF(C17<250,"$100-250M","$250-500M"))) -> $250-500M
A18: FIP | B18: FTAI Infrastructure | C18: 321.45 | D18: Land / entitlement developer | E18: Value unlocked by entitlements, zoning, plats and permits on specific parcels | F18: Planning commission & council agendas; plat approvals; Census BPS; county deed and assessor records | G18: Port/terminal and power assets - local and state permits | H18: Unverified | I18: 3 | J18: 3 | K18: =IF(C18>=50,1,0) -> 1 | L18: =IF(H18="0 (checked)",2,IF(H18="Unverified",1,IF(H18="1 (checked)",0.5,0))) -> 1 | M18: =I18+J18+K18+L18 -> 8 | N18: =IF(C18<25,"Nano (<$25M)",IF(C18<100,"$25-100M",IF(C18<250,"$100-250M","$250-500M"))) -> $250-500M
A19: NODK | B19: NI Holdings | C19: 305.66 | D19: State-regulated P&C insurer | E19: State insurance departments approve rates; catastrophe reforms in specific states | F19: SERFF rate filings; state insurance dept market-share and complaint data | G19: North Dakota | H19: Unverified | I19: 3 | J19: 3 | K19: =IF(C19>=50,1,0) -> 1 | L19: =IF(H19="0 (checked)",2,IF(H19="Unverified",1,IF(H19="1 (checked)",0.5,0))) -> 1 | M19: =I19+J19+K19+L19 -> 8 | N19: =IF(C19<25,"Nano (<$25M)",IF(C19<100,"$25-100M",IF(C19<250,"$100-250M","$250-500M"))) -> $250-500M
A20: ARL | B20: American Realty Investors | C20: 293.16 | D20: Land / entitlement developer | E20: Value unlocked by entitlements, zoning, plats and permits on specific parcels | F20: Planning commission & council agendas; plat approvals; Census BPS; county deed and assessor records | G20: Parent of TCI | H20: Unverified | I20: 3 | J20: 3 | K20: =IF(C20>=50,1,0) -> 1 | L20: =IF(H20="0 (checked)",2,IF(H20="Unverified",1,IF(H20="1 (checked)",0.5,0))) -> 1 | M20: =I20+J20+K20+L20 -> 8 | N20: =IF(C20<25,"Nano (<$25M)",IF(C20<100,"$25-100M",IF(C20<250,"$100-250M","$250-500M"))) -> $250-500M
A21: MTRX | B21: Matrix Service | C21: 283.49 | D21: Public-works contractor | E21: Revenue won through state DOT, municipal and utility contract lettings | F21: State DOT bid lettings & awards; municipal procurement portals; utility capex filings | H21: Unverified | I21: 3 | J21: 3 | K21: =IF(C21>=50,1,0) -> 1 | L21: =IF(H21="0 (checked)",2,IF(H21="Unverified",1,IF(H21="1 (checked)",0.5,0))) -> 1 | M21: =I21+J21+K21+L21 -> 8 | N21: =IF(C21<25,"Nano (<$25M)",IF(C21<100,"$25-100M",IF(C21<250,"$100-250M","$250-500M"))) -> $250-500M
A22: PCYO | B22: Pure Cycle | C22: 266.03 | D22: Regulated utility | E22: State commission sets rates; customer additions come from local development approvals | F22: State PUC/SCC rate dockets; county subdivision approvals; Census Building Permits Survey | G22: Sky Ranch plats/permits; activist proxy contest (Aug 2026) | H22: 0 (checked) | I22: 3 | J22: 2 | K22: =IF(C22>=50,1,0) -> 1 | L22: =IF(H22="0 (checked)",2,IF(H22="Unverified",1,IF(H22="1 (checked)",0.5,0))) -> 2 | M22: =I22+J22+K22+L22 -> 8 | N22: =IF(C22<25,"Nano (<$25M)",IF(C22<100,"$25-100M",IF(C22<250,"$100-250M","$250-500M"))) -> $250-500M
A23: BRT | B23: BRT Apartments | C23: 256.81 | D23: Apartment owner | E23: Rents shaped by local rent rules and new-supply permits in specific metros | F23: Local rent boards (e.g., NYC Rent Guidelines Board); multifamily permits; eviction filings; property-tax assessments | H23: Unverified | I23: 3 | J23: 3 | K23: =IF(C23>=50,1,0) -> 1 | L23: =IF(H23="0 (checked)",2,IF(H23="Unverified",1,IF(H23="1 (checked)",0.5,0))) -> 1 | M23: =I23+J23+K23+L23 -> 8 | N23: =IF(C23<25,"Nano (<$25M)",IF(C23<100,"$25-100M",IF(C23<250,"$100-250M","$250-500M"))) -> $250-500M
A24: KINS | B24: Kingstone Companies | C24: 254.49 | D24: State-regulated P&C insurer | E24: State insurance departments approve rates; catastrophe reforms in specific states | F24: SERFF rate filings; state insurance dept market-share and complaint data | G24: New York DFS | H24: Unverified | I24: 3 | J24: 3 | K24: =IF(C24>=50,1,0) -> 1 | L24: =IF(H24="0 (checked)",2,IF(H24="Unverified",1,IF(H24="1 (checked)",0.5,0))) -> 1 | M24: =I24+J24+K24+L24 -> 8 | N24: =IF(C24<25,"Nano (<$25M)",IF(C24<100,"$25-100M",IF(C24<250,"$100-250M","$250-500M"))) -> $250-500M
A25: AIV | B25: Aimco | C25: 253.83 | D25: Apartment owner | E25: Rents shaped by local rent rules and new-supply permits in specific metros | F25: Local rent boards (e.g., NYC Rent Guidelines Board); multifamily permits; eviction filings; property-tax assessments | H25: Unverified | I25: 3 | J25: 3 | K25: =IF(C25>=50,1,0) -> 1 | L25: =IF(H25="0 (checked)",2,IF(H25="Unverified",1,IF(H25="1 (checked)",0.5,0))) -> 1 | M25: =I25+J25+K25+L25 -> 8 | N25: =IF(C25<25,"Nano (<$25M)",IF(C25<100,"$25-100M",IF(C25<250,"$100-250M","$250-500M"))) -> $250-500M
A26: LMNR | B26: Limoneira | C26: 213.6 | D26: Land / entitlement developer | E26: Value unlocked by entitlements, zoning, plats and permits on specific parcels | F26: Planning commission & council agendas; plat approvals; Census BPS; county deed and assessor records | G26: Santa Paula, CA housing development & water | H26: Unverified | I26: 3 | J26: 3 | K26: =IF(C26>=50,1,0) -> 1 | L26: =IF(H26="0 (checked)",2,IF(H26="Unverified",1,IF(H26="1 (checked)",0.5,0))) -> 1 | M26: =I26+J26+K26+L26 -> 8 | N26: =IF(C26<25,"Nano (<$25M)",IF(C26<100,"$25-100M",IF(C26<250,"$100-250M","$250-500M"))) -> $100-250M
A27: CHCI | B27: Comstock Holding | C27: 187.44 | D27: Land / entitlement developer | E27: Value unlocked by entitlements, zoning, plats and permits on specific parcels | F27: Planning commission & council agendas; plat approvals; Census BPS; county deed and assessor records | G27: Reston/Loudoun, VA transit-oriented development | H27: Unverified | I27: 3 | J27: 3 | K27: =IF(C27>=50,1,0) -> 1 | L27: =IF(H27="0 (checked)",2,IF(H27="Unverified",1,IF(H27="1 (checked)",0.5,0))) -> 1 | M27: =I27+J27+K27+L27 -> 8 | N27: =IF(C27<25,"Nano (<$25M)",IF(C27<100,"$25-100M",IF(C27<250,"$100-250M","$250-500M"))) -> $100-250M
A28: NEN | B28: New England Realty Associates | C28: 173.41 | D28: Apartment owner | E28: Rents shaped by local rent rules and new-supply permits in specific metros | F28: Local rent boards (e.g., NYC Rent Guidelines Board); multifamily permits; eviction filings; property-tax assessments | G28: Boston-area apartments - rent policy | H28: Unverified | I28: 3 | J28: 3 | K28: =IF(C28>=50,1,0) -> 1 | L28: =IF(H28="0 (checked)",2,IF(H28="Unverified",1,IF(H28="1 (checked)",0.5,0))) -> 1 | M28: =I28+J28+K28+L28 -> 8 | N28: =IF(C28<25,"Nano (<$25M)",IF(C28<100,"$25-100M",IF(C28<250,"$100-250M","$250-500M"))) -> $100-250M
A29: ESOA | B29: Energy Services of America | C29: 171.85 | D29: Public-works contractor | E29: Revenue won through state DOT, municipal and utility contract lettings | F29: State DOT bid lettings & awards; municipal procurement portals; utility capex filings | G29: Utility & broadband contractor - WV/Appalachia | H29: Unverified | I29: 3 | J29: 3 | K29: =IF(C29>=50,1,0) -> 1 | L29: =IF(H29="0 (checked)",2,IF(H29="Unverified",1,IF(H29="1 (checked)",0.5,0))) -> 1 | M29: =I29+J29+K29+L29 -> 8 | N29: =IF(C29<25,"Nano (<$25M)",IF(C29<100,"$25-100M",IF(C29<250,"$100-250M","$250-500M"))) -> $100-250M
A30: ELME | B30: Elme Communities | C30: 155.52 | D30: Apartment owner | E30: Rents shaped by local rent rules and new-supply permits in specific metros | F30: Local rent boards (e.g., NYC Rent Guidelines Board); multifamily permits; eviction filings; property-tax assessments | G30: DC-area apartments | H30: Unverified | I30: 3 | J30: 3 | K30: =IF(C30>=50,1,0) -> 1 | L30: =IF(H30="0 (checked)",2,IF(H30="Unverified",1,IF(H30="1 (checked)",0.5,0))) -> 1 | M30: =I30+J30+K30+L30 -> 8 | N30: =IF(C30<25,"Nano (<$25M)",IF(C30<100,"$25-100M",IF(C30<250,"$100-250M","$250-500M"))) -> $100-250M
A31: OZ | B31: Belpointe PREP | C31: 152.09 | D31: Land / entitlement developer | E31: Value unlocked by entitlements, zoning, plats and permits on specific parcels | F31: Planning commission & council agendas; plat approvals; Census BPS; county deed and assessor records | G31: Opportunity-zone developments; local approvals | H31: Unverified | I31: 3 | J31: 3 | K31: =IF(C31>=50,1,0) -> 1 | L31: =IF(H31="0 (checked)",2,IF(H31="Unverified",1,IF(H31="1 (checked)",0.5,0))) -> 1 | M31: =I31+J31+K31+L31 -> 8 | N31: =IF(C31<25,"Nano (<$25M)",IF(C31<100,"$25-100M",IF(C31<250,"$100-250M","$250-500M"))) -> $100-250M
A32: CLPR | B32: Clipper Realty | C32: 133.8 | D32: Apartment owner | E32: Rents shaped by local rent rules and new-supply permits in specific metros | F32: Local rent boards (e.g., NYC Rent Guidelines Board); multifamily permits; eviction filings; property-tax assessments | G32: NYC rent-stabilized units - Rent Guidelines Board votes | H32: Unverified | I32: 3 | J32: 3 | K32: =IF(C32>=50,1,0) -> 1 | L32: =IF(H32="0 (checked)",2,IF(H32="Unverified",1,IF(H32="1 (checked)",0.5,0))) -> 1 | M32: =I32+J32+K32+L32 -> 8 | N32: =IF(C32<25,"Nano (<$25M)",IF(C32<100,"$25-100M",IF(C32<250,"$100-250M","$250-500M"))) -> $100-250M
A33: SMID | B33: Smith-Midland | C33: 118.82 | D33: Public-works contractor | E33: Revenue won through state DOT, municipal and utility contract lettings | F33: State DOT bid lettings & awards; municipal procurement portals; utility capex filings | G33: State DOT precast/barrier demand | H33: Unverified | I33: 3 | J33: 3 | K33: =IF(C33>=50,1,0) -> 1 | L33: =IF(H33="0 (checked)",2,IF(H33="Unverified",1,IF(H33="1 (checked)",0.5,0))) -> 1 | M33: =I33+J33+K33+L33 -> 8 | N33: =IF(C33<25,"Nano (<$25M)",IF(C33<100,"$25-100M",IF(C33<250,"$100-250M","$250-500M"))) -> $100-250M
A34: BHM | B34: Bluerock Homes Trust | C34: 107.56 | D34: Apartment owner | E34: Rents shaped by local rent rules and new-supply permits in specific metros | F34: Local rent boards (e.g., NYC Rent Guidelines Board); multifamily permits; eviction filings; property-tax assessments | H34: Unverified | I34: 3 | J34: 3 | K34: =IF(C34>=50,1,0) -> 1 | L34: =IF(H34="0 (checked)",2,IF(H34="Unverified",1,IF(H34="1 (checked)",0.5,0))) -> 1 | M34: =I34+J34+K34+L34 -> 8 | N34: =IF(C34<25,"Nano (<$25M)",IF(C34<100,"$25-100M",IF(C34<250,"$100-250M","$250-500M"))) -> $100-250M
A35: STHO | B35: Star Holdings | C35: 102.03 | D35: Land / entitlement developer | E35: Value unlocked by entitlements, zoning, plats and permits on specific parcels | F35: Planning commission & council agendas; plat approvals; Census BPS; county deed and assessor records | G35: Asbury Park, NJ waterfront redevelopment | H35: Unverified | I35: 3 | J35: 3 | K35: =IF(C35>=50,1,0) -> 1 | L35: =IF(H35="0 (checked)",2,IF(H35="Unverified",1,IF(H35="1 (checked)",0.5,0))) -> 1 | M35: =I35+J35+K35+L35 -> 8 | N35: =IF(C35<25,"Nano (<$25M)",IF(C35<100,"$25-100M",IF(C35<250,"$100-250M","$250-500M"))) -> $100-250M
A36: SHIM | B36: Shimmick | C36: 99.62 | D36: Public-works contractor | E36: Revenue won through state DOT, municipal and utility contract lettings | F36: State DOT bid lettings & awards; municipal procurement portals; utility capex filings | G36: Water & public infrastructure | H36: Unverified | I36: 3 | J36: 3 | K36: =IF(C36>=50,1,0) -> 1 | L36: =IF(H36="0 (checked)",2,IF(H36="Unverified",1,IF(H36="1 (checked)",0.5,0))) -> 1 | M36: =I36+J36+K36+L36 -> 8 | N36: =IF(C36<25,"Nano (<$25M)",IF(C36<100,"$25-100M",IF(C36<250,"$100-250M","$250-500M"))) -> $25-100M
A37: SRG | B37: Seritage Growth Properties | C37: 88.43 | D37: Land / entitlement developer | E37: Value unlocked by entitlements, zoning, plats and permits on specific parcels | F37: Planning commission & council agendas; plat approvals; Census BPS; county deed and assessor records | G37: Liquidating former Sears sites - local entitlements drive sale values | H37: Unverified | I37: 3 | J37: 3 | K37: =IF(C37>=50,1,0) -> 1 | L37: =IF(H37="0 (checked)",2,IF(H37="Unverified",1,IF(H37="1 (checked)",0.5,0))) -> 1 | M37: =I37+J37+K37+L37 -> 8 | N37: =IF(C37<25,"Nano (<$25M)",IF(C37<100,"$25-100M",IF(C37<250,"$100-250M","$250-500M"))) -> $25-100M
A38: INTG | B38: InterGroup | C38: 68.57 | D38: Hotel owner | E38: Local hotel demand, convention calendars, city policy | F38: City hotel/occupancy-tax reports; convention-center calendars; local permits | G38: Hilton SF Financial District - SF hotel tax, conventions | H38: 0 (checked) | I38: 2 | J38: 3 | K38: =IF(C38>=50,1,0) -> 1 | L38: =IF(H38="0 (checked)",2,IF(H38="Unverified",1,IF(H38="1 (checked)",0.5,0))) -> 2 | M38: =I38+J38+K38+L38 -> 8 | N38: =IF(C38<25,"Nano (<$25M)",IF(C38<100,"$25-100M",IF(C38<250,"$100-250M","$250-500M"))) -> $25-100M
A39: BLNK | B39: Blink Charging | C39: 61.38 | D39: Public-works contractor | E39: Revenue won through state DOT, municipal and utility contract lettings | F39: State DOT bid lettings & awards; municipal procurement portals; utility capex filings | G39: Municipal EV charging contracts | H39: Unverified | I39: 3 | J39: 3 | K39: =IF(C39>=50,1,0) -> 1 | L39: =IF(H39="0 (checked)",2,IF(H39="Unverified",1,IF(H39="1 (checked)",0.5,0))) -> 1 | M39: =I39+J39+K39+L39 -> 8 | N39: =IF(C39<25,"Nano (<$25M)",IF(C39<100,"$25-100M",IF(C39<250,"$100-250M","$250-500M"))) -> $25-100M
A40: FLL | B40: Full House Resorts | C40: 50.94 | D40: Regional gaming / racing | E40: State gaming & racing commissions license and tax; local approvals for expansions | F40: Monthly state gaming-revenue reports by property; racing commission minutes; city development agendas | G40: Illinois & Colorado gaming boards - monthly property revenue | H40: Unverified | I40: 3 | J40: 3 | K40: =IF(C40>=50,1,0) -> 1 | L40: =IF(H40="0 (checked)",2,IF(H40="Unverified",1,IF(H40="1 (checked)",0.5,0))) -> 1 | M40: =I40+J40+K40+L40 -> 8 | N40: =IF(C40<25,"Nano (<$25M)",IF(C40<100,"$25-100M",IF(C40<250,"$100-250M","$250-500M"))) -> $25-100M
A41: GYRO | B41: Gyrodyne | C41: 10.51 | D41: Land / entitlement developer | E41: Value unlocked by entitlements, zoning, plats and permits on specific parcels | F41: Planning commission & council agendas; plat approvals; Census BPS; county deed and assessor records | G41: Liquidating; Smithtown & Cortlandt, NY approvals | H41: 0 (checked) | I41: 3 | J41: 3 | K41: =IF(C41>=50,1,0) -> 0 | L41: =IF(H41="0 (checked)",2,IF(H41="Unverified",1,IF(H41="1 (checked)",0.5,0))) -> 2 | M41: =I41+J41+K41+L41 -> 8 | N41: =IF(C41<25,"Nano (<$25M)",IF(C41<100,"$25-100M",IF(C41<250,"$100-250M","$250-500M"))) -> Nano (<$25M)
...

Sheet Archetypes
A1: Archetypes - what drives each group and which public data the platform ingests
A3: Archetype | B3: Local-gov driver | C3: Public data to ingest | D3: Local-gov intensity | E3: Data edge
A4: Community bank | B4: Loan growth, deposits and credit tied to one local economy and its real estate | C4: FFIEC call reports (quarterly, bank-level); FDIC Summary of Deposits (county share); HMDA mortgage data; county permits & deed records | D4: 2 | E4: 3
A5: Regulated utility | B5: State commission sets rates; customer additions come from local development approvals | C5: State PUC/SCC rate dockets; county subdivision approvals; Census Building Permits Survey | D5: 3 | E5: 2
A6: Energy project developer | B6: County zoning/siting votes and state incentive programs decide whether projects get built | C6: County zoning agendas (siting moratoriums); state program dockets (community solar, LCFS); interconnection queues | D6: 3 | E6: 2
A7: Land / entitlement developer | B7: Value unlocked by entitlements, zoning, plats and permits on specific parcels | C7: Planning commission & council agendas; plat approvals; Census BPS; county deed and assessor records | D7: 3 | E7: 3
A8: Property owner (commercial) | B8: Asset values and leasing in a handful of metros; zoning and property-tax decisions | C8: County assessor/recorder data; local building permits; zoning/rezoning agendas | D8: 2 | E8: 2
A9: Apartment owner | B9: Rents shaped by local rent rules and new-supply permits in specific metros | C9: Local rent boards (e.g., NYC Rent Guidelines Board); multifamily permits; eviction filings; property-tax assessments | D9: 3 | E9: 3
A10: RE transaction platform | B10: Revenue tracks home/commercial transaction counts in specific markets | C10: County deed recordings (e.g., NYC ACRIS); transfer-tax receipts; MLS-derived counts | D10: 1 | E10: 3
A11: Hotel owner | B11: Local hotel demand, convention calendars, city policy | C11: City hotel/occupancy-tax reports; convention-center calendars; local permits | D11: 2 | E11: 3
A12: Farmland / water rights | B12: Water rights, county ag zoning and land conversion approvals | C12: State water-rights filings & allocations; USDA land values; county records | D12: 2 | E12: 2
A13: Regional gaming / racing | B13: State gaming & racing commissions license and tax; local approvals for expansions | C13: Monthly state gaming-revenue reports by property; racing commission minutes; city development agendas | D13: 3 | E13: 3
A14: Oil & gas producer / royalty | B14: Production, permits and spacing on specific acreage set by state regulators | C14: State oil & gas commission well permits & monthly production (Texas RRC, NM OCD, Oklahoma OCC, Louisiana SONRIS, etc.) | D14: 2 | E14: 3
A15: Midstream / energy infrastructure | B15: State/local permits and government supply contracts | C15: State permit dockets; utility/government contract awards; port authority agendas | D15: 2 | E15: 2
... A22: Government-funded services | B22: State/municipal contracts, subsidies and licensing | C22: Municipal contract registers (e.g., NYC Checkbook); state subsidy rate schedules; licensing boards | D22: 3 | E22: 2

Sheet Excluded
A1: Screened out of the industry lists, and why
A3: Reason | B3: Examples
A4: Foreign operations / domicile | B4: e.g., ELLO, WAVE, HTOO, LPA, LND, GTE, NRT, ANNA, MSC, CVEO, ATLX, most China/HK/Singapore-based listings in education, construction and real estate
A5: Canadian/foreign mine juniors | B5: e.g., NMG, PHOS, LZM, GRO, VGZ, TRX, CMCL, FURY, GLDG - permits sit outside US local government
A6: Consumer / tech with no local-gov link | B6: e.g., leisure brands, Chegg, Skillsoft, Gogo, Cogent, most 'renewable' microcap startups
A7: Above $500M | B7: e.g., YORW ($502M) just misses - consider raising the cap to $750M in v2
A8: Liquidating / delisting | B8: STRS (plan of liquidation, intends to delist) - GYRO and SRG kept because entitlements drive their liquidation value
A9: Status unclear | B9: GREE (Greenidge) - no current listing data found; verify name/ticker before adding

Sheet Method
A1: Method, scoring and caveats
A3: 1. Universe: StockAnalysis.com industry pages (pulled Oct 16, 2026) for ~30 industries where local or state government is a plausible driver: regional banks, utilities, real estate & REITs, land, construction, waste, gaming, lodging, farmland, oil & gas, midstream, mining, telecom, P&C insurance, healthcare facilities, education.
A4: 2. Filter: market cap below $500M, US operations, not a shell. Archetype assigned by industry plus company knowledge; notes added where a specific local body or dataset is known.
A5: 3. Priority = Local-gov intensity (1-3) + Data edge (1-3) + Tradable (1 if >= $50M) + Coverage points (2 if verified zero, 1 if unverified, 0.5 if one analyst, 0 if two or more). Max 9. Intensity and data-edge scores are judgment calls set per archetype on the Archetypes tab - edit them there in the build or override per row.
A6: 4. Coverage: only 14 names are verified so far. Run coverage_check.py on your own computer (it uses Yahoo Finance via the yfinance package) to fill column H for every name; Priority recalculates automatically. Confirm zero-coverage names on Bloomberg (ANR) or CapIQ before saying 'uncovered' in print - free sources miss single-broker coverage.
A7: 5. Expect many community banks to have 1-3 regional-broker analysts (Janney, Hovde, Piper, KBW, Stephens, DA Davidson). They stay in the universe because call-report and deposit data are a real edge even with light coverage.
A8: 6. Market caps are as of Oct 16, 2026 and will drift. A few figures look off (e.g., CABO, WHLR) and are flagged in the Note column - check before use.
A9: 7. Not yet included: OTC-traded companies (likely several hundred more zero-coverage names: community banks, small utilities, land companies), and NYSE/Nasdaq names in industries not pulled here. Adding OTC is the obvious v2.
